Workbook

Sheet محصولات
A1: ورود گروهی موجودی تهران — محصولات فعلی + استخراج گروه عطر (25 مرداد 1405)
A2: ستون‌های عکس فقط نام فایل را می‌گیرند؛ فایل‌های عکس را کنار اکسل یا در ZIP با همین نام‌ها قرار دهید.
A4: کد محصول | B4: نام محصول | C4: توضیحات دستی | D4: قیمت خرید (دلار) | E4: سایز | F4: وزن (گرم) | G4: موقعیت | H4: دسته‌بندی | I4: عکس ۱ | J4: عکس ۲ | K4: عکس ۳ | L4: لینک تلگرام ۱ | M4: لینک تلگرام ۲ | N4: قیمت نهایی (تومان)
A5: IMP-0001 | B5: کیف دستی Mk | C5: کیف دستی Mk 90$ ۴۶۶gr ابعاد: ١٠*٢٠*٢٢ فقط رنگ سفید صورتی موجود هست برای ثبت سفارش به آیدی زیر مراجعه کنید : @f_ati_a | D5: 90 | F5: 466 | G5: کانادا | H5: کیف | I5: export_photo_1031@01-02-2026_11-43-13.jpg | N5: =D5*تنظیمات!$B$3*تنظیمات!$B$5+(F5/1000)*تنظیمات!$B$4
A6: IMP-0002 | B6: کیف دستی متوسط Mk | C6: کیف دستی متوسط Mk 690gr ❌ : ابعاد 30*23*9 99$ برای ثبت سفارش به آیدی زیر مراجعه کنید : @f_ati_a | D6: 99 | F6: 690 | G6: کانادا | H6: کیف | I6: export_photo_1035@02-02-2026_13-20-43.jpg | N6: =D6*تنظیمات!$B$3*تنظیمات!$B$5+(F6/1000)*تنظیمات!$B$4
A7: IMP-0003 | B7: پاستیل مولتی ویتامین روزانه مخصوص بزرگسالان برند ویتافیوژن مولتی ویتز 250 عددی ساخت آمریکا | C7: پاستیل مولتی ویتامین روزانه مخصوص بزرگسالان برند ویتافیوژن مولتی ویتز 250 عددی ساخت آمریکا مولتی‌ویتامین روزانه مولتی‌ویتز فیوژن یک مولتی ویتامین خوشمزه است که جایگزینی عالی و راحت برای قرص‌های سنتی و سخت بلعیده می‌شود. این پاستیل های لذت‌بخش که از ترکیبی قدرتمند از ویتامین‌ها، مواد معدنی و طعم‌های میوه ساخته شده‌اند، مملو از 12 ماده مغذی ضروری از جمله ویتامین‌های A، B، C، D، E، B6، B12، بیوتین و غیره هستند. به طور ویژه برای رفع نیازهای سلامتی بزرگسالان فرموله شده است حاوی آنتی اکسیدان ویتامین C و E 5 ویتامین B با قدرت بالا برای حمایت از انرژی سلولی بدون گلوتن، بدون لبنیات، بدون طعم دهنده های مصنوعی، بدون شربت ذرت با فروکتوز بالا و بدون رنگ های مصنوعی FD&C 250 عددی ساخت آمریکا 07/2026 انقضا 732gr 17.99$ با قیمت باورنکردنی 😱۱۰$😱😱 تقدیمتون میشه برای ثبت سفارش به آیدی زیر مراجعه کنید : @f_ati_a | D7: 10 | F7: 732 | G7: کانادا | H7: دارو و سلامتی | I7: export_photo_1038@03-02-2026_12-17-11.jpg | N7: =D7*تنظیمات!$B$3*تنظیمات!$B$5+(F7/1000)*تنظیمات!$B$4
A8: IMP-0004 | B8: کفش آدیداس | C8: کفش آدیداس 8,5 72$🤑 544gr 26,5cm ❌ برای ثبت سفارش به آیدی زیر مراجعه کنید : @f_ati_a | D8: 72 | F8: 544 | G8: کانادا | H8: کفش | I8: export_photo_1039@04-02-2026_14-24-12.jpg | N8: =D8*تنظیمات!$B$3*تنظیمات!$B$5+(F8/1000)*تنظیمات!$B$4
A9: IMP-0005 | B9: کفش Mk | C9: کفش Mk 60$ 8 464gr 8,5 458gr برای ثبت سفارش به آیدی زیر مراجعه کنید : ❌ @f_ati_a موجود تهران ✨ ارسال فوری 🚚 خرید بلک‌فرایدی کانادا 🇨🇦 قیمت استثنایی و محدود 👗 | D9: 60 | F9: 464 | G9: تهران | H9: کفش | I9: export_photo_1044@04-02-2026_14-27-38.jpg | N9: =D9*تنظیمات!$B$3*تنظیمات!$B$5+(F9/1000)*تنظیمات!$B$4
A10: IMP-0006 | B10: آشواگاندا (Ashwagandha) 🌱 | C10: آشواگاندا (Ashwagandha) 🌱 گیاه معروف آیورودایی که این روزها برای مدیریت استرس و بالا بردن کیفیت حال عمومی خیلی مورد توجهه. ✨ چرا انقدر محبوبه؟ ✅ کمک به کاهش استرس و تنش‌های روزمره ✅ کمک به بهبود خلق‌وخو و تعادل ذهنی ✅ افزایش سطح انرژی و کاهش احساس خستگی ✅ کمک به تمرکز و عملکرد ذهنی بهتر ✅ پشتیبانی از سیستم ایمنی بدن ✅ ایجاد حس سرزندگی و حالِ بهتر در طول روز ✅ کمک به بهبود کیفیت خواب 💪 در کنار این‌ها، بعضی تحقیقات نشون دادن که آشواگاندا می‌تونه در موارد زیر نقش حمایتی داشته باشه: ▫️ کمک به تنظیم قند خون و کاهش التهاب ▫️ کمک به کاهش هورمون استرس (کورتیزول) ▫️ پشتیبانی از عملکرد مغز، حافظه و یادگیری ▫️ کمک به بهبود توان بدنی و ریکاوری عضلات ▫️ کمک به تعادل هورمونی در برخی افراد ▫️ کمک به بهبود میل جنسی و انرژی عمومی 19.99$ | D10: 19.99 | G10: کانادا | H10: دارو و سلامتی | I10: export_photo_1047@08-02-2026_17-08-19.jpg | N10: =D10*تنظیمات!$B$3*تنظیمات!$B$5+(F10/1000)*تنظیمات!$B$4
A11: IMP-0007 | B11: منیزیوم سیترات | C11: منیزیوم سیترات شکلی از منیزیم با قابلیت جذب آسان برای افرادی که اسید معده کمی دارند، منحصراً در کاستکو، بدون گلوتن، کمک به رشد و حفظ سلامت استخوان‌ها و دندان‌ها، کمک به متابولیسم مواد مغذی، مواد تشکیل دهنده با کیفیت بالا، بدون رنگ یا شیرین کننده مصنوعی، غیر GMO، سازگار با سیاره زمین، آزمایش شده برای آلرژن‌ها شکلی از منیزیم با قابلیت جذب آسان برای افرادی که اسید معده کمی دارند، منحصراً در کاستکو، بدون گلوتن، کمک به... بیشتر ببینید منیزیم قابل جذب برای اسید معده کم: ایده‌آل برای افرادی که سطح اسید معده کمی دارند حمایت از سلامت استخوان و دندان: کمک به رشد و حفظ سلامت استخوان‌ها و دندان‌ها کمک به متابولیسم مواد مغذی: کمک به متابولیسم کربوهیدرات‌ها، پروتئین‌ها و چربی‌ها 34.99$ 360gr 2030 برای ثبت سفارش به آیدی زیر مراجعه کنید : @f_ati_a | D11: 34.99 | F11: 360 | G11: کانادا | H11: دارو و سلامتی | I11: export_photo_1048@09-02-2026_11-16-28.jpg | N11: =D11*تنظیمات!$B$3*تنظیمات!$B$5+(F11/1000)*تنظیمات!$B$4
A12: IMP-0008 | B12: osteo joint ease | C12: osteo joint ease ضد التهاب: ترکیب گلوکزامین و کندرویتین سولفات در کنار متیل سولفونیل متان (MSM)، منگنز، بور و هیالورونیک اسید، به تأمین بلوک‌های سازنده کلیدی که بافت مفصلی سالم را تشکیل می‌دهند، کمک می‌کند. این مواد مغذی همچنین از تجزیه نامطلوب غضروف که مشخصه آرتروز است، جلوگیری می‌کنند و به تسکین التهاب مفاصل و درد و ناراحتی آرتروز کمک می‌کنند. مسکن طبیعی درد: این فرمول نوآورانه حاوی InflamEase ثبت اختراع شده، ترکیبی هم‌افزایی از گیاهان آنتی‌اکسیدان، ضدالتهاب و تسکین‌دهنده درد (از جمله بوسولیا و کورکومین از زردچوبه) است که درد و التهاب را به سرعت تسکین می‌دهد. این یک فرمول ۱۰۰٪ طبیعی است که درد مرتبط با آرتروز را برطرف می‌کند و از تخریب غضروف محافظت می‌کند. 🌺32$ 418gr 2028 برای ثبت سفارش به آیدی زیر مراجعه کنید : @f_ati_a | D12: 32 | F12: 418 | G12: کانادا | H12: دارو و سلامتی | I12: export_photo_1049@09-02-2026_11-19-12.jpg | N12: =D12*تنظیمات!$B$3*تنظیمات!$B$5+(F12/1000)*تنظیمات!$B$4
A13: IMP-0009 | B13: قرص ویتامین D3 | C13: قرص ویتامین D3 یک D3فرموله شده با Quali-D، طبیعی ممتاز، هر قرص ویتامین D Jamieson 1000 یک واحد بین‌المللی ویتامین D ضروری را فراهم می‌کند و به بدن در جذب کلسیم کمک می‌کند و باعث رشد و رشد استخوان‌ها و دندان‌های قوی و سالم می‌شود ٧٨gr 9.99$ 9/2029 برای ثبت سفارش به آیدی زیر مراجعه کنید : @f_ati_a | D13: 9.99 | F13: 78 | G13: کانادا | H13: دارو و سلامتی | I13: export_photo_1050@09-02-2026_11-23-58.jpg | N13: =D13*تنظیمات!$B$3*تنظیمات!$B$5+(F13/1000)*تنظیمات!$B$4
A14: IMP-0010 | B14: D3450 | C14: D3450 ویتامین دی جمیسون 450 عدد Jamieson Vitamin D3 2500IU سلامت قلب و عروق بهبود خلق‌وخو و سلامت روان تقویت سیستم ایمنی کاهش خطر ابتلا به پوکی استخوان پیشگیری از کمبود ویتامین D 12$ 106gr 9/2028 برای ثبت سفارش به آیدی زیر مراجعه کنید : @f_ati_a | D14: 12 | F14: 106 | G14: کانادا | H14: دارو و سلامتی | I14: export_photo_1051@09-02-2026_11-30-36.jpg | N14: =D14*تنظیمات!$B$3*تنظیمات!$B$5+(F14/1000)*تنظیمات!$B$4
A15: IMP-0011 | B15: Glucosamine | C15: Glucosamine condition گلوکزآمین کندرویتین و ام اس ام کرکلند Kirkland Glucosamine Chondroitin & MSM • به تسکین درد مفاصل مرتبط با آرتروز کمک می کند • از تخریب غضروف محافظت می کند • عامل حفظ سلامت غضروف و مفاصل • بهبود درد و عملکرد مفاصل در افراد مبتلا به استئوآرتریت، به ویژه زانو یا لگن • کاهش تخریب غضروف مفصل و پیشرفت بیماری های مفصلی مرتبط با افزایش سن 300 کپسول 32.99$ 628gr 2028 برای ثبت سفارش به آیدی زیر مراجعه کنید : @f_ati_a | D15: 32.99 | F15: 628 | G15: کانادا | H15: دارو و سلامتی | I15: export_photo_1052@09-02-2026_11-35-36.jpg | N15: =D15*تنظیمات!$B$3*تنظیمات!$B$5+(F15/1000)*تنظیمات!$B$4
A16: IMP-0012 | B16: گلوکوزامین و کندرویتین | C16: کارایی دو ترکیبی که به طور طبیعی در غضروف یافت می شوند را در یک فرمول مناسب برای محافظت در برابر زوال غضروف، تسکین درد، و کاهش سفتی و حساسیت در افراد مبتلا به استئوآرتریت ترکیب کرده ایم. در غضروف، گلوکزامین به رشد سلول ها و حفظ ساختار کمک می کند محصول کانادا مشخصات گلوکوزامین سولفات 500mg کندروین سولفات 400mg تعداد در یک بسته ۱۴۰ Mr/2029 32$ 440gr برای ثبت سفارش به آیدی زیر مراجعه کنید : @f_ati_a | D16: 32 | F16: 440 | G16: کانادا | H16: دارو و سلامتی | I16: export_photo_1053@09-02-2026_11-59-42.jpg | N16: =D16*تنظیمات!$B$3*تنظیمات!$B$5+(F16/1000)*تنظیمات!$B$4
A17: IMP-0013 | B17: قرص ایبوپروفن و متوکاربامول | C17: قرص ایبوپروفن و متوکاربامول تسکین دردهای عضلانی و کمر پلاتینیوم ضد درد شل کننده عضلات 14,99$ 100gr ۸۰ عدد کپسول mr/2028 برای ثبت سفارش به آیدی زیر مراجعه کنید : @f_ati_a | D17: 14.99 | F17: 100 | G17: کانادا | H17: دارو و سلامتی | I17: export_photo_1056@09-02-2026_12-02-06.jpg | N17: =D17*تنظیمات!$B$3*تنظیمات!$B$5+(F17/1000)*تنظیمات!$B$4
A18: IMP-0014 | B18: قرص | C18: #قرص ### Focus Factor Brain Supplement & Complete Multivitamin اگر به دنبال یک مکمل عالی برای تقویت حافظه، تمرکز و عملکرد مغز هستید، Focus Factor گزینه‌ای بی‌نظیر است. این مکمل نه تنها یک مولتی‌ویتامین کامل است، بلکه شامل ترکیبات خاصی است که به بهبود سلامت مغز کمک می‌کند. #### ویژگی‌ها: - تقویت حافظه و تمرکز: فرمول بالینی آزمایش شده این محصول به بهبود حافظه، تمرکز و توانایی تفکر کمک می‌کند. - مواد مغذی برای مغز: ترکیباتی چون زینک، منیزیم، ویتامین‌های B6 و B12، و ویتامین D به همراه Bacopa Monnieri و تیروسین برای تغذیه مغز و بهبود کارایی آن به کار رفته‌اند. - کیفیت بالا: Focus Factor فاقد رنگ‌های مصنوعی، شیرین‌کننده‌های مصنوعی و شربت ذرت با فروکتوز بالا است و از مواد باکیفیت استفاده می‌کند. #### مزایای کلیدی: - افزایش توانایی شناختی: ترکیبات موجود در این مکمل به بهبود عملکرد شناختی و افزایش توانایی‌های ذهنی کمک می‌کنند. - تامین انرژی روزانه ٢٣۶gr 4/2028 ۱۲۰ عددی ۲۸.۹۹$: @f_ati_a | D18: 28.99 | F18: 236 | G18: کانادا | H18: دارو و سلامتی | I18: export_photo_1057@09-02-2026_13-05-28.jpg | N18: =D18*تنظیمات!$B$3*تنظیمات!$B$5+(F18/1000)*تنظیمات!$B$4
A19: IMP-0015 | B19: omegaQsterols | C19: omegaQsterols omega3&co10 امگا و‌کو کیو 10 200تایی 382gوزن قیمت ۳۳.۹۹$ Al/2028 این قرص حاوی ترکیبی از امگا-3، CoQ10 و استرول‌های گیاهی است که به سلامت قلب و عروق، کاهش تری‌گلیسیرید و کلسترول، و حمایت از سلامت شناختی و مغز کمک می‌کند. همچنین، می‌تواند دفعات سردردهای میگرنی و علائم مرتبط را کاهش دهد. این محصول دارای کپسول‌های نرم با آزادسازی تأخیری و جذب بالاتر از فرمول‌های استاندارد است. برای ثبت سفارش به آیدی زیر مراجعه کنید : @f_ati_a | D19: 33.99 | G19: کانادا | H19: دارو و سلامتی | I19: export_photo_1058@09-02-2026_13-12-20.jpg | N19: =D19*تنظیمات!$B$3*تنظیمات!$B$5+(F19/1000)*تنظیمات!$B$4
A20: IMP-0016 | B20: Ferrous Sulfate | C20: Ferrous Sulfate آیا احساس خستگی و کمبود انرژی می‌کنید؟ فقر آهن ممکن است دلیل اصلی این مشکلات باشد، اما حالا با Ferrous Gluconate از Wampole، مشکلی نیست! این قرص حاوی آهن مهمی است که به تولید و عملکرد صحیح گلبول های قرمز خون کمک می‌کند، بنابراین شما می‌توانید انرژی لازم برای فعالیت‌های روزمره خود را به دست آورید و از خستگی رها شوید. با مصرف روزانه یک قرص، به همراه غذا، شما می‌توانید بهترین نتیجه را به دست آورید. همچنین به یاد داشته باشید که این قرص را با فاصله‌ای از مصرف دیگر داروها یا مکمل‌های غذایی مصرف کنید. با Ferrous Gluconate، به بهترین شکل مراقبت از سلامتی خود را داشته باشید و از زندگی بهتری لذت ببرید!" 😍 ۱۰۰ عددی ۹.۹۹$ Ma/2027 وزن ۷۲g برای ثبت سفارش به آیدی زیر مراجعه کنید : @f_ati_a | D20: 9.99 | F20: 72 | G20: کانادا | H20: دارو و سلامتی | I20: export_photo_1059@09-02-2026_13-15-23.jpg | N20: =D20*تنظیمات!$B$3*تنظیمات!$B$5+(F20/1000)*تنظیمات!$B$4
A21: IMP-0017 | B21: کیف lole | C21: کیف lole آبی 20$ 244gr برای ثبت سفارش به آیدی زیر مراجعه کنید : @f_ati_a موجود تهران ✨ ارسال فوری 🚚 خرید بلک‌فرایدی کانادا 🇨🇦 قیمت استثنایی و محدود 👗 | D21: 20 | F21: 244 | G21: تهران | H21: کیف | I21: export_photo_1061@16-02-2026_12-09-32.jpg | N21: =D21*تنظیمات!$B$3*تنظیمات!$B$5+(F21/1000)*تنظیمات!$B$4
A22: IMP-0018 | B22: بلوز شلوار مخمل Velour | C22: بلوز شلوار مخمل Velour 28.99$ 664gr M نصف زیر بغل ۶۲cm نصف دور کمر ۳۶cm برای ثبت سفارش به آیدی زیر مراجعه کنید : @f_ati_a | D22: 28.99 | F22: 664 | G22: کانادا | H22: لباس | I22: export_photo_1065@16-02-2026_12-33-30.jpg | N22: =D22*تنظیمات!$B$3*تنظیمات!$B$5+(F22/1000)*تنظیمات!$B$4
A23: IMP-0019 | B23: کلاه ck | C23: کلاه ck 23$ 100gr برای ثبت سفارش به آیدی زیر مراجعه کنید : @f_ati_a موجود تهران ✨ ارسال فوری 🚚 خرید بلک‌فرایدی کانادا 🇨🇦 قیمت استثنایی و محدود 👗 | D23: 23 | F23: 100 | G23: تهران | H23: اکسسوری | I23: export_photo_1069@18-02-2026_12-38-32.jpg | N23: =D23*تنظیمات!$B$3*تنظیمات!$B$5+(F23/1000)*تنظیمات!$B$4
A24: IMP-0020 | B24: کلاه ck | C24: کلاه ck 23$ 106gr ❌ برای ثبت سفارش به آیدی زیر مراجعه کنید : @f_ati_a موجود تهران ✨ ارسال فوری 🚚 خرید بلک‌فرایدی کانادا 🇨🇦 قیمت استثنایی و محدود 👗 | D24: 23 | F24: 106 | G24: تهران | H24: اکسسوری | I24: export_photo_1073@18-02-2026_12-48-49.jpg | N24: =D24*تنظیمات!$B$3*تنظیمات!$B$5+(F24/1000)*تنظیمات!$B$4
A25: IMP-0021 | B25: کلاه تامی | C25: کلاه تامی 19$ 110gr و کرم برای ثبت سفارش به آیدی زیر مراجعه کنید : @f_ati_a موجود تهران ✨ ارسال فوری 🚚 خرید بلک‌فرایدی کانادا 🇨🇦 قیمت استثنایی و محدود 👗 | D25: 19 | F25: 110 | G25: تهران | H25: اکسسوری | I25: export_photo_1074@18-02-2026_12-56-13.jpg | N25: =D25*تنظیمات!$B$3*تنظیمات!$B$5+(F25/1000)*تنظیمات!$B$4
A26: IMP-0022 | B26: mk | C26: mk سایز7.5 49$ موجودی کانادا | D26: 49 | G26: کانادا | H26: سایر | I26: export_photo_1075@26-05-2026_05-16-01.jpg | N26: =D26*تنظیمات!$B$3*تنظیمات!$B$5+(F26/1000)*تنظیمات!$B$4
A27: IMP-0023 | B27: سایز ۱۰ | C27: سایز ۱۰ guess 35$ موجودی کانادا | D27: 35 | G27: کانادا | H27: سایر | I27: export_photo_1078@26-05-2026_05-18-40.jpg | N27: =D27*تنظیمات!$B$3*تنظیمات!$B$5+(F27/1000)*تنظیمات!$B$4
A28: IMP-0024 | B28: اسکچرز | C28: اسکچرز ۲۵$ 4us 36 23cm | D28: 25 | G28: کانادا | H28: کفش | I28: export_photo_1082@26-05-2026_05-23-24.jpg | N28: =D28*تنظیمات!$B$3*تنظیمات!$B$5+(F28/1000)*تنظیمات!$B$4
A29: IMP-0025 | B29: R78 Wind Nylon | C29: R78 Wind Nylon 39$ مردانه پوما این کتونی ترکیبی از استایل ترندی امروزی و طراحی الهام‌گرفته از دهه ۷۰ داره ✨ مدل PUMA R78 Wind Nylon با فیت اسپرت و ترکیب متفاوت رنگ‌ها و متریال‌ها، ظاهر خاص و چشمگیری ایجاد کرده. همچنین با کفی SoftFoam+ طراحی شده که باعث میشه پا توی طول روز راحت و نرم بمونه 👟 کوشن و راحتی خیلی خوبی داره و برای استفاده روزمره عالیه سایز 9us | D29: 39 | G29: کانادا | H29: کفش | I29: export_photo_1085@26-05-2026_05-27-17.jpg | N29: =D29*تنظیمات!$B$3*تنظیمات!$B$5+(F29/1000)*تنظیمات!$B$4
A30: IMP-0026 | B30: Dkny | C30: Dkny 35$ سایز ۳۸ | D30: 35 | G30: کانادا | H30: سایر | I30: export_photo_1088@26-05-2026_05-30-39.jpg | N30: =D30*تنظیمات!$B$3*تنظیمات!$B$5+(F30/1000)*تنظیمات!$B$4
A31: IMP-0027 | B31: کفش.old navy | C31: کفش.old navy 8 276gr موجودی تهران 😇قیمت در حراجی الیکا شاپ . 15$😇 برای ثبت سفارش به آیدی زیر مراجعه کنید : @fatemehalamdar68 @rshb63 | D31: 15 | F31: 276 | G31: کانادا | H31: کفش | I31: export_photo_1096@11-06-2026_00-28-05.jpg | N31: =D31*تنظیمات!$B$3*تنظیمات!$B$5+(F31/1000)*تنظیمات!$B$4
A32: IMP-0028 | B32: صندل مردانه cross | C32: صندل مردانه cross M/10 w/12 638gr موجودی تهران 😇قیمت در حراجی الیکا شاپ . 60$😇 برای ثبت سفارش به آیدی زیر مراجعه کنید : @Rh_reyhan @f_ati_a | D32: 60 | F32: 638 | G32: کانادا | H32: کفش | I32: export_photo_1103@11-06-2026_00-30-02.jpg | N32: =D32*تنظیمات!$B$3*تنظیمات!$B$5+(F32/1000)*تنظیمات!$B$4
A33: IMP-0029 | B33: کفش | C33: کفش adidas مردانه 9 828gr موجودی تهران 😇قیمت در حراجی الیکا شاپ . 59$😇 برای ثبت سفارش به آیدی زیر مراجعه کنید : @Rh_reyhan @f_ati_a | D33: 59 | F33: 828 | G33: کانادا | H33: کفش | I33: export_photo_1104@11-06-2026_00-44-09.jpg | N33: =D33*تنظیمات!$B$3*تنظیمات!$B$5+(F33/1000)*تنظیمات!$B$4
A34: IMP-0030 | B34: کفش | C34: کفش Mk 9 800gr موجودی تهران 😇قیمت در حراجی الیکا شاپ . 59$😇 ❌ برای ثبت سفارش به آیدی زیر مراجعه کنید : @Rh_reyhan @f_ati_a | D34: 59 | F34: 800 | G34: کانادا | H34: کفش | I34: export_photo_1107@11-06-2026_00-45-20.jpg | N34: =D34*تنظیمات!$B$3*تنظیمات!$B$5+(F34/1000)*تنظیمات!$B$4
A35: IMP-0031 | B35: کفش بچگانه | C35: کفش بچگانه puma uk:1 us:2c 458gr موجودی تهران 😇قیمت در حراجی الیکا شاپ . 29$😇 برای ثبت سفارش به آیدی زیر مراجعه کنید : @Rh_reyhan @f_ati_a | D35: 29 | F35: 458 | G35: کانادا | H35: کفش | I35: export_photo_1110@11-06-2026_00-48-48.jpg | N35: =D35*تنظیمات!$B$3*تنظیمات!$B$5+(F35/1000)*تنظیمات!$B$4
A36: IMP-0032 | B36: کیف کراس بادیMk | C36: کیف کراس بادیMk 380gr ابعاد: 16*24*5 82$ رنگ: وانیلی قهوه ای برای ثبت سفارش به آیدی زیر مراجعه کنید : 🇮🇷🇮🇷ارسال سریع تهران | D36: 82 | F36: 380 | G36: کانادا | H36: کیف | I36: export_photo_1122@14-07-2026_19-15-38.jpg | N36: =D36*تنظیمات!$B$3*تنظیمات!$B$5+(F36/1000)*تنظیمات!$B$4
A37: IMP-0033 | B37: کیف کراس بادی Mk | C37: کیف کراس بادی Mk 75$ ۴۰۰gr ابعاد: 14*29*7 در دو رنگ : وانیلی مشکی برای ثبت سفارش به آیدی زیر مراجعه کنید : 🇮🇷🇮🇷ارسال سریع تهران | D37: 75 | F37: 400 | G37: کانادا | H37: کیف | I37: export_photo_1130@14-07-2026_19-17-33.jpg | N37: =D37*تنظیمات!$B$3*تنظیمات!$B$5+(F37/1000)*تنظیمات!$B$4
A38: IMP-0034 | B38: خلاصه ابعاد | C38: خلاصه ابعاد 📏 27.3 × 19.1 × 10.2 سانتی‌متر (عرض × ارتفاع × عمق) 119$🇮🇷🇮🇷 ارسال سریع تهران | D38: 119 | G38: کانادا | H38: سایر | I38: export_photo_1134@14-07-2026_19-23-12.jpg | N38: =D38*تنظیمات!$B$3*تنظیمات!$B$5+(F38/1000)*تنظیمات!$B$4
A39: IMP-0035 | B39: تامی | C39: تامی 8.5us 39 6us 36 از ۲۱۹$ شده ۲۹$ 🇨🇦ارسالی از کانادا | D39: 29 | G39: کانادا | H39: سایر | I39: export_photo_1139@15-07-2026_21-56-37.jpg | N39: =D39*تنظیمات!$B$3*تنظیمات!$B$5+(F39/1000)*تنظیمات!$B$4
A40: IMP-0036 | B40: • ساخته شده از ۱۰۰٪ پلی‌یورتان (PU) با دوام و کیفیت بالا | C40: • ساخته شده از ۱۰۰٪ پلی‌یورتان (PU) با دوام و کیفیت بالا • دارای دو دسته برای حمل راحت • مزین به لوگوی فلزی مونوگرام در قسمت جلو • دارای یک محفظه اصلی جادار با بسته‌شدن زیپی برای نگهداری ایمن وسایل • طراحی ساده و یکدست (Solid) با ظاهری شیک و مینیمال • ابعاد تقریبی: ۴۵ × ۳۲ × ۱۵ سانتی‌متر • تمیز کردن آسان با یک دستمال مرطوب کیف تامی ۴۲$ قیمت قبل تخفیف ۱۲۹$ با خرید این کیف ۸۷$ save می کنید 🇨🇦ارسالی از کانادا | D40: 87 | G40: کانادا | H40: کیف | I40: export_photo_1145@16-07-2026_02-22-14.jpg | N40: =D40*تنظیمات!$B$3*تنظیمات!$B$5+(F40/1000)*تنظیمات!$B$4
A41: IMP-0037 | B41: کیف کوچک و کاربردی | C41: � کیف کوچک و کاربردی 📏 ابعاد به سانتی‌متر: طول: 18 سانتی‌متر عرض: 5 سانتی‌متر ارتفاع: 10.8 سانتی‌متر ✨ دارای جیب داخلی برای نظم بیشتر 🔒 زیپ‌دار 💛 یراق‌آلات طلایی آنتیک 🌿 جنس: کتان (Canvas) با آستر پلی‌استر جمع‌وجور، سبک و مناسب استفاده روزمره یا مهمانی‌های سبک 💫 موجودی تهران ارسال سریع ۳۵$ | D41: 35 | G41: کانادا | H41: کیف | I41: export_photo_1151@16-07-2026_02-40-09.jpg | N41: =D41*تنظیمات!$B$3*تنظیمات!$B$5+(F41/1000)*تنظیمات!$B$4
...

Sheet راهنما
A1: راهنمای ورود محصولات در بات
A3: ۱ | B3: هر ردیف در شیت محصولات یک محصول است.
A4: ۲ | B4: نام فایل عکس‌ها را در ستون‌های عکس ۱ تا عکس ۳ وارد کنید؛ خود عکس را داخل سلول نچسبانید.
A5: ۳ | B5: عکس‌ها را کنار فایل Excel قرار دهید یا همه را همراه Excel در یک ZIP بگذارید.
A6: ۴ | B6: نام فایل‌ها باید دقیقاً با مقدار ستون‌های عکس یکسان باشد؛ پسوند jpg، jpeg یا png قابل استفاده است.
A7: ۵ | B7: اگر محصول بیشتر از ۳ عکس دارد، عکس‌های اضافه را با الگوی SKU-001-4.jpg نام‌گذاری کنید؛ در نسخه بات می‌توانیم ستون عکس‌های بیشتر اضافه کنیم.
A8: ۶ | B8: توضیحات دستی اختیاری است؛ اگر خالی باشد، بات می‌تواند بعداً با AI توضیح فروشگاهی تولید کند.
A9: ۷ | B9: قیمت نهایی از شیت تنظیمات محاسبه می‌شود و بات هنگام ورود اطلاعات دوباره آن را محاسبه می‌کند.
A10: ۸ | B10: فایل نهایی را از منوی بات با دکمه «📥 ورود اکسل» ارسال کنید.
A11: ۹ | B11: محصولات گروه عطر از فایل Telegram استخراج شده‌اند؛ عکس‌ها در ستون‌های عکس با نام فایل ثبت شده‌اند.
A12: ۱۰ | B12: برای نمایش عکس‌ها در Railway، خود فایل‌های عکس باید جداگانه در بات آپلود شوند؛ Excel فقط اطلاعات و نام فایل را منتقل می‌کند.

Sheet تنظیمات
A1: تنظیمات محاسبه قیمت
A3: نرخ دلار (تومان) | B3: 200000
A4: هزینه حمل هر کیلو (تومان) | B4: 8000000
A5: ضریب قیمت | B5: 1.5
A7: فرمول | B7: (قیمت دلار × نرخ دلار × ضریب) + (وزن به کیلو × هزینه حمل)
